<robot name="machine1">
	<link name="0">
		<visual>
			<geometry>
				<cylinder length="3.758516854510998" radius="0.27757569185273906"/>
			</geometry>
		</visual>
		<collision>
			<geometry>
				<cylinder length="3.758516854510998" radius="0.27757569185273906"/>
			</geometry>
		</collision>
		<inertial>
			<mass value="0.9097650248502112"/>
			<inertia ixx="0.03" iyy="0.03" izz="0.03" ixy="0" ixz="0" iyz="0"/>
		</inertial>
	</link>
	<link name="11">
		<visual>
			<geometry>
				<cylinder length="2.756844747817835" radius="0.49926077965895044"/>
			</geometry>
		</visual>
		<collision>
			<geometry>
				<cylinder length="2.756844747817835" radius="0.49926077965895044"/>
			</geometry>
		</collision>
		<inertial>
			<mass value="2.158823233381241"/>
			<inertia ixx="0.03" iyy="0.03" izz="0.03" ixy="0" ixz="0" iyz="0"/>
		</inertial>
	</link>
	<link name="22">
		<visual>
			<geometry>
				<cylinder length="2.075845222486958" radius="0.36340269098112454"/>
			</geometry>
		</visual>
		<collision>
			<geometry>
				<cylinder length="2.075845222486958" radius="0.36340269098112454"/>
			</geometry>
		</collision>
		<inertial>
			<mass value="0.8612339062416339"/>
			<inertia ixx="0.03" iyy="0.03" izz="0.03" ixy="0" ixz="0" iyz="0"/>
		</inertial>
	</link>
	<link name="33">
		<visual>
			<geometry>
				<cylinder length="3.2854636229483303" radius="0.6066100657098417"/>
			</geometry>
		</visual>
		<collision>
			<geometry>
				<cylinder length="3.2854636229483303" radius="0.6066100657098417"/>
			</geometry>
		</collision>
		<inertial>
			<mass value="3.798094451092633"/>
			<inertia ixx="0.03" iyy="0.03" izz="0.03" ixy="0" ixz="0" iyz="0"/>
		</inertial>
	</link>
	<link name="44">
		<visual>
			<geometry>
				<cylinder length="4.312771017976796" radius="0.4042393650210545"/>
			</geometry>
		</visual>
		<collision>
			<geometry>
				<cylinder length="4.312771017976796" radius="0.4042393650210545"/>
			</geometry>
		</collision>
		<inertial>
			<mass value="2.2140298872108053"/>
			<inertia ixx="0.03" iyy="0.03" izz="0.03" ixy="0" ixz="0" iyz="0"/>
		</inertial>
	</link>
	<link name="45">
		<visual>
			<geometry>
				<cylinder length="4.312771017976796" radius="0.4042393650210545"/>
			</geometry>
		</visual>
		<collision>
			<geometry>
				<cylinder length="4.312771017976796" radius="0.4042393650210545"/>
			</geometry>
		</collision>
		<inertial>
			<mass value="2.2140298872108053"/>
			<inertia ixx="0.03" iyy="0.03" izz="0.03" ixy="0" ixz="0" iyz="0"/>
		</inertial>
	</link>
	<link name="46">
		<visual>
			<geometry>
				<cylinder length="4.312771017976796" radius="0.4042393650210545"/>
			</geometry>
		</visual>
		<collision>
			<geometry>
				<cylinder length="4.312771017976796" radius="0.4042393650210545"/>
			</geometry>
		</collision>
		<inertial>
			<mass value="2.2140298872108053"/>
			<inertia ixx="0.03" iyy="0.03" izz="0.03" ixy="0" ixz="0" iyz="0"/>
		</inertial>
	</link>
	<link name="47">
		<visual>
			<geometry>
				<cylinder length="4.312771017976796" radius="0.4042393650210545"/>
			</geometry>
		</visual>
		<collision>
			<geometry>
				<cylinder length="4.312771017976796" radius="0.4042393650210545"/>
			</geometry>
		</collision>
		<inertial>
			<mass value="2.2140298872108053"/>
			<inertia ixx="0.03" iyy="0.03" izz="0.03" ixy="0" ixz="0" iyz="0"/>
		</inertial>
	</link>
	<link name="48">
		<visual>
			<geometry>
				<cylinder length="4.312771017976796" radius="0.4042393650210545"/>
			</geometry>
		</visual>
		<collision>
			<geometry>
				<cylinder length="4.312771017976796" radius="0.4042393650210545"/>
			</geometry>
		</collision>
		<inertial>
			<mass value="2.2140298872108053"/>
			<inertia ixx="0.03" iyy="0.03" izz="0.03" ixy="0" ixz="0" iyz="0"/>
		</inertial>
	</link>
	<link name="49">
		<visual>
			<geometry>
				<cylinder length="4.312771017976796" radius="0.4042393650210545"/>
			</geometry>
		</visual>
		<collision>
			<geometry>
				<cylinder length="4.312771017976796" radius="0.4042393650210545"/>
			</geometry>
		</collision>
		<inertial>
			<mass value="2.2140298872108053"/>
			<inertia ixx="0.03" iyy="0.03" izz="0.03" ixy="0" ixz="0" iyz="0"/>
		</inertial>
	</link>
	<link name="310">
		<visual>
			<geometry>
				<cylinder length="3.2854636229483303" radius="0.6066100657098417"/>
			</geometry>
		</visual>
		<collision>
			<geometry>
				<cylinder length="3.2854636229483303" radius="0.6066100657098417"/>
			</geometry>
		</collision>
		<inertial>
			<mass value="3.798094451092633"/>
			<inertia ixx="0.03" iyy="0.03" izz="0.03" ixy="0" ixz="0" iyz="0"/>
		</inertial>
	</link>
	<link name="411">
		<visual>
			<geometry>
				<cylinder length="4.312771017976796" radius="0.4042393650210545"/>
			</geometry>
		</visual>
		<collision>
			<geometry>
				<cylinder length="4.312771017976796" radius="0.4042393650210545"/>
			</geometry>
		</collision>
		<inertial>
			<mass value="2.2140298872108053"/>
			<inertia ixx="0.03" iyy="0.03" izz="0.03" ixy="0" ixz="0" iyz="0"/>
		</inertial>
	</link>
	<link name="412">
		<visual>
			<geometry>
				<cylinder length="4.312771017976796" radius="0.4042393650210545"/>
			</geometry>
		</visual>
		<collision>
			<geometry>
				<cylinder length="4.312771017976796" radius="0.4042393650210545"/>
			</geometry>
		</collision>
		<inertial>
			<mass value="2.2140298872108053"/>
			<inertia ixx="0.03" iyy="0.03" izz="0.03" ixy="0" ixz="0" iyz="0"/>
		</inertial>
	</link>
	<link name="413">
		<visual>
			<geometry>
				<cylinder length="4.312771017976796" radius="0.4042393650210545"/>
			</geometry>
		</visual>
		<collision>
			<geometry>
				<cylinder length="4.312771017976796" radius="0.4042393650210545"/>
			</geometry>
		</collision>
		<inertial>
			<mass value="2.2140298872108053"/>
			<inertia ixx="0.03" iyy="0.03" izz="0.03" ixy="0" ixz="0" iyz="0"/>
		</inertial>
	</link>
	<link name="414">
		<visual>
			<geometry>
				<cylinder length="4.312771017976796" radius="0.4042393650210545"/>
			</geometry>
		</visual>
		<collision>
			<geometry>
				<cylinder length="4.312771017976796" radius="0.4042393650210545"/>
			</geometry>
		</collision>
		<inertial>
			<mass value="2.2140298872108053"/>
			<inertia ixx="0.03" iyy="0.03" izz="0.03" ixy="0" ixz="0" iyz="0"/>
		</inertial>
	</link>
	<link name="415">
		<visual>
			<geometry>
				<cylinder length="4.312771017976796" radius="0.4042393650210545"/>
			</geometry>
		</visual>
		<collision>
			<geometry>
				<cylinder length="4.312771017976796" radius="0.4042393650210545"/>
			</geometry>
		</collision>
		<inertial>
			<mass value="2.2140298872108053"/>
			<inertia ixx="0.03" iyy="0.03" izz="0.03" ixy="0" ixz="0" iyz="0"/>
		</inertial>
	</link>
	<link name="416">
		<visual>
			<geometry>
				<cylinder length="4.312771017976796" radius="0.4042393650210545"/>
			</geometry>
		</visual>
		<collision>
			<geometry>
				<cylinder length="4.312771017976796" radius="0.4042393650210545"/>
			</geometry>
		</collision>
		<inertial>
			<mass value="2.2140298872108053"/>
			<inertia ixx="0.03" iyy="0.03" izz="0.03" ixy="0" ixz="0" iyz="0"/>
		</inertial>
	</link>
	<link name="317">
		<visual>
			<geometry>
				<cylinder length="3.2854636229483303" radius="0.6066100657098417"/>
			</geometry>
		</visual>
		<collision>
			<geometry>
				<cylinder length="3.2854636229483303" radius="0.6066100657098417"/>
			</geometry>
		</collision>
		<inertial>
			<mass value="3.798094451092633"/>
			<inertia ixx="0.03" iyy="0.03" izz="0.03" ixy="0" ixz="0" iyz="0"/>
		</inertial>
	</link>
	<link name="418">
		<visual>
			<geometry>
				<cylinder length="4.312771017976796" radius="0.4042393650210545"/>
			</geometry>
		</visual>
		<collision>
			<geometry>
				<cylinder length="4.312771017976796" radius="0.4042393650210545"/>
			</geometry>
		</collision>
		<inertial>
			<mass value="2.2140298872108053"/>
			<inertia ixx="0.03" iyy="0.03" izz="0.03" ixy="0" ixz="0" iyz="0"/>
		</inertial>
	</link>
	<link name="419">
		<visual>
			<geometry>
				<cylinder length="4.312771017976796" radius="0.4042393650210545"/>
			</geometry>
		</visual>
		<collision>
			<geometry>
				<cylinder length="4.312771017976796" radius="0.4042393650210545"/>
			</geometry>
		</collision>
		<inertial>
			<mass value="2.2140298872108053"/>
			<inertia ixx="0.03" iyy="0.03" izz="0.03" ixy="0" ixz="0" iyz="0"/>
		</inertial>
	</link>
	<link name="420">
		<visual>
			<geometry>
				<cylinder length="4.312771017976796" radius="0.4042393650210545"/>
			</geometry>
		</visual>
		<collision>
			<geometry>
				<cylinder length="4.312771017976796" radius="0.4042393650210545"/>
			</geometry>
		</collision>
		<inertial>
			<mass value="2.2140298872108053"/>
			<inertia ixx="0.03" iyy="0.03" izz="0.03" ixy="0" ixz="0" iyz="0"/>
		</inertial>
	</link>
	<link name="421">
		<visual>
			<geometry>
				<cylinder length="4.312771017976796" radius="0.4042393650210545"/>
			</geometry>
		</visual>
		<collision>
			<geometry>
				<cylinder length="4.312771017976796" radius="0.4042393650210545"/>
			</geometry>
		</collision>
		<inertial>
			<mass value="2.2140298872108053"/>
			<inertia ixx="0.03" iyy="0.03" izz="0.03" ixy="0" ixz="0" iyz="0"/>
		</inertial>
	</link>
	<link name="422">
		<visual>
			<geometry>
				<cylinder length="4.312771017976796" radius="0.4042393650210545"/>
			</geometry>
		</visual>
		<collision>
			<geometry>
				<cylinder length="4.312771017976796" radius="0.4042393650210545"/>
			</geometry>
		</collision>
		<inertial>
			<mass value="2.2140298872108053"/>
			<inertia ixx="0.03" iyy="0.03" izz="0.03" ixy="0" ixz="0" iyz="0"/>
		</inertial>
	</link>
	<link name="423">
		<visual>
			<geometry>
				<cylinder length="4.312771017976796" radius="0.4042393650210545"/>
			</geometry>
		</visual>
		<collision>
			<geometry>
				<cylinder length="4.312771017976796" radius="0.4042393650210545"/>
			</geometry>
		</collision>
		<inertial>
			<mass value="2.2140298872108053"/>
			<inertia ixx="0.03" iyy="0.03" izz="0.03" ixy="0" ixz="0" iyz="0"/>
		</inertial>
	</link>
	<link name="224">
		<visual>
			<geometry>
				<cylinder length="2.075845222486958" radius="0.36340269098112454"/>
			</geometry>
		</visual>
		<collision>
			<geometry>
				<cylinder length="2.075845222486958" radius="0.36340269098112454"/>
			</geometry>
		</collision>
		<inertial>
			<mass value="0.8612339062416339"/>
			<inertia ixx="0.03" iyy="0.03" izz="0.03" ixy="0" ixz="0" iyz="0"/>
		</inertial>
	</link>
	<link name="325">
		<visual>
			<geometry>
				<cylinder length="3.2854636229483303" radius="0.6066100657098417"/>
			</geometry>
		</visual>
		<collision>
			<geometry>
				<cylinder length="3.2854636229483303" radius="0.6066100657098417"/>
			</geometry>
		</collision>
		<inertial>
			<mass value="3.798094451092633"/>
			<inertia ixx="0.03" iyy="0.03" izz="0.03" ixy="0" ixz="0" iyz="0"/>
		</inertial>
	</link>
	<link name="426">
		<visual>
			<geometry>
				<cylinder length="4.312771017976796" radius="0.4042393650210545"/>
			</geometry>
		</visual>
		<collision>
			<geometry>
				<cylinder length="4.312771017976796" radius="0.4042393650210545"/>
			</geometry>
		</collision>
		<inertial>
			<mass value="2.2140298872108053"/>
			<inertia ixx="0.03" iyy="0.03" izz="0.03" ixy="0" ixz="0" iyz="0"/>
		</inertial>
	</link>
	<link name="427">
		<visual>
			<geometry>
				<cylinder length="4.312771017976796" radius="0.4042393650210545"/>
			</geometry>
		</visual>
		<collision>
			<geometry>
				<cylinder length="4.312771017976796" radius="0.4042393650210545"/>
			</geometry>
		</collision>
		<inertial>
			<mass value="2.2140298872108053"/>
			<inertia ixx="0.03" iyy="0.03" izz="0.03" ixy="0" ixz="0" iyz="0"/>
		</inertial>
	</link>
	<link name="428">
		<visual>
			<geometry>
				<cylinder length="4.312771017976796" radius="0.4042393650210545"/>
			</geometry>
		</visual>
		<collision>
			<geometry>
				<cylinder length="4.312771017976796" radius="0.4042393650210545"/>
			</geometry>
		</collision>
		<inertial>
			<mass value="2.2140298872108053"/>
			<inertia ixx="0.03" iyy="0.03" izz="0.03" ixy="0" ixz="0" iyz="0"/>
		</inertial>
	</link>
	<link name="429">
		<visual>
			<geometry>
				<cylinder length="4.312771017976796" radius="0.4042393650210545"/>
			</geometry>
		</visual>
		<collision>
			<geometry>
				<cylinder length="4.312771017976796" radius="0.4042393650210545"/>
			</geometry>
		</collision>
		<inertial>
			<mass value="2.2140298872108053"/>
			<inertia ixx="0.03" iyy="0.03" izz="0.03" ixy="0" ixz="0" iyz="0"/>
		</inertial>
	</link>
	<link name="430">
		<visual>
			<geometry>
				<cylinder length="4.312771017976796" radius="0.4042393650210545"/>
			</geometry>
		</visual>
		<collision>
			<geometry>
				<cylinder length="4.312771017976796" radius="0.4042393650210545"/>
			</geometry>
		</collision>
		<inertial>
			<mass value="2.2140298872108053"/>
			<inertia ixx="0.03" iyy="0.03" izz="0.03" ixy="0" ixz="0" iyz="0"/>
		</inertial>
	</link>
	<link name="431">
		<visual>
			<geometry>
				<cylinder length="4.312771017976796" radius="0.4042393650210545"/>
			</geometry>
		</visual>
		<collision>
			<geometry>
				<cylinder length="4.312771017976796" radius="0.4042393650210545"/>
			</geometry>
		</collision>
		<inertial>
			<mass value="2.2140298872108053"/>
			<inertia ixx="0.03" iyy="0.03" izz="0.03" ixy="0" ixz="0" iyz="0"/>
		</inertial>
	</link>
	<link name="332">
		<visual>
			<geometry>
				<cylinder length="3.2854636229483303" radius="0.6066100657098417"/>
			</geometry>
		</visual>
		<collision>
			<geometry>
				<cylinder length="3.2854636229483303" radius="0.6066100657098417"/>
			</geometry>
		</collision>
		<inertial>
			<mass value="3.798094451092633"/>
			<inertia ixx="0.03" iyy="0.03" izz="0.03" ixy="0" ixz="0" iyz="0"/>
		</inertial>
	</link>
	<link name="433">
		<visual>
			<geometry>
				<cylinder length="4.312771017976796" radius="0.4042393650210545"/>
			</geometry>
		</visual>
		<collision>
			<geometry>
				<cylinder length="4.312771017976796" radius="0.4042393650210545"/>
			</geometry>
		</collision>
		<inertial>
			<mass value="2.2140298872108053"/>
			<inertia ixx="0.03" iyy="0.03" izz="0.03" ixy="0" ixz="0" iyz="0"/>
		</inertial>
	</link>
	<link name="434">
		<visual>
			<geometry>
				<cylinder length="4.312771017976796" radius="0.4042393650210545"/>
			</geometry>
		</visual>
		<collision>
			<geometry>
				<cylinder length="4.312771017976796" radius="0.4042393650210545"/>
			</geometry>
		</collision>
		<inertial>
			<mass value="2.2140298872108053"/>
			<inertia ixx="0.03" iyy="0.03" izz="0.03" ixy="0" ixz="0" iyz="0"/>
		</inertial>
	</link>
	<link name="435">
		<visual>
			<geometry>
				<cylinder length="4.312771017976796" radius="0.4042393650210545"/>
			</geometry>
		</visual>
		<collision>
			<geometry>
				<cylinder length="4.312771017976796" radius="0.4042393650210545"/>
			</geometry>
		</collision>
		<inertial>
			<mass value="2.2140298872108053"/>
			<inertia ixx="0.03" iyy="0.03" izz="0.03" ixy="0" ixz="0" iyz="0"/>
		</inertial>
	</link>
	<link name="436">
		<visual>
			<geometry>
				<cylinder length="4.312771017976796" radius="0.4042393650210545"/>
			</geometry>
		</visual>
		<collision>
			<geometry>
				<cylinder length="4.312771017976796" radius="0.4042393650210545"/>
			</geometry>
		</collision>
		<inertial>
			<mass value="2.2140298872108053"/>
			<inertia ixx="0.03" iyy="0.03" izz="0.03" ixy="0" ixz="0" iyz="0"/>
		</inertial>
	</link>
	<link name="437">
		<visual>
			<geometry>
				<cylinder length="4.312771017976796" radius="0.4042393650210545"/>
			</geometry>
		</visual>
		<collision>
			<geometry>
				<cylinder length="4.312771017976796" radius="0.4042393650210545"/>
			</geometry>
		</collision>
		<inertial>
			<mass value="2.2140298872108053"/>
			<inertia ixx="0.03" iyy="0.03" izz="0.03" ixy="0" ixz="0" iyz="0"/>
		</inertial>
	</link>
	<link name="438">
		<visual>
			<geometry>
				<cylinder length="4.312771017976796" radius="0.4042393650210545"/>
			</geometry>
		</visual>
		<collision>
			<geometry>
				<cylinder length="4.312771017976796" radius="0.4042393650210545"/>
			</geometry>
		</collision>
		<inertial>
			<mass value="2.2140298872108053"/>
			<inertia ixx="0.03" iyy="0.03" izz="0.03" ixy="0" ixz="0" iyz="0"/>
		</inertial>
	</link>
	<link name="339">
		<visual>
			<geometry>
				<cylinder length="3.2854636229483303" radius="0.6066100657098417"/>
			</geometry>
		</visual>
		<collision>
			<geometry>
				<cylinder length="3.2854636229483303" radius="0.6066100657098417"/>
			</geometry>
		</collision>
		<inertial>
			<mass value="3.798094451092633"/>
			<inertia ixx="0.03" iyy="0.03" izz="0.03" ixy="0" ixz="0" iyz="0"/>
		</inertial>
	</link>
	<link name="440">
		<visual>
			<geometry>
				<cylinder length="4.312771017976796" radius="0.4042393650210545"/>
			</geometry>
		</visual>
		<collision>
			<geometry>
				<cylinder length="4.312771017976796" radius="0.4042393650210545"/>
			</geometry>
		</collision>
		<inertial>
			<mass value="2.2140298872108053"/>
			<inertia ixx="0.03" iyy="0.03" izz="0.03" ixy="0" ixz="0" iyz="0"/>
		</inertial>
	</link>
	<link name="441">
		<visual>
			<geometry>
				<cylinder length="4.312771017976796" radius="0.4042393650210545"/>
			</geometry>
		</visual>
		<collision>
			<geometry>
				<cylinder length="4.312771017976796" radius="0.4042393650210545"/>
			</geometry>
		</collision>
		<inertial>
			<mass value="2.2140298872108053"/>
			<inertia ixx="0.03" iyy="0.03" izz="0.03" ixy="0" ixz="0" iyz="0"/>
		</inertial>
	</link>
	<link name="442">
		<visual>
			<geometry>
				<cylinder length="4.312771017976796" radius="0.4042393650210545"/>
			</geometry>
		</visual>
		<collision>
			<geometry>
				<cylinder length="4.312771017976796" radius="0.4042393650210545"/>
			</geometry>
		</collision>
		<inertial>
			<mass value="2.2140298872108053"/>
			<inertia ixx="0.03" iyy="0.03" izz="0.03" ixy="0" ixz="0" iyz="0"/>
		</inertial>
	</link>
	<link name="443">
		<visual>
			<geometry>
				<cylinder length="4.312771017976796" radius="0.4042393650210545"/>
			</geometry>
		</visual>
		<collision>
			<geometry>
				<cylinder length="4.312771017976796" radius="0.4042393650210545"/>
			</geometry>
		</collision>
		<inertial>
			<mass value="2.2140298872108053"/>
			<inertia ixx="0.03" iyy="0.03" izz="0.03" ixy="0" ixz="0" iyz="0"/>
		</inertial>
	</link>
	<link name="444">
		<visual>
			<geometry>
				<cylinder length="4.312771017976796" radius="0.4042393650210545"/>
			</geometry>
		</visual>
		<collision>
			<geometry>
				<cylinder length="4.312771017976796" radius="0.4042393650210545"/>
			</geometry>
		</collision>
		<inertial>
			<mass value="2.2140298872108053"/>
			<inertia ixx="0.03" iyy="0.03" izz="0.03" ixy="0" ixz="0" iyz="0"/>
		</inertial>
	</link>
	<link name="445">
		<visual>
			<geometry>
				<cylinder length="4.312771017976796" radius="0.4042393650210545"/>
			</geometry>
		</visual>
		<collision>
			<geometry>
				<cylinder length="4.312771017976796" radius="0.4042393650210545"/>
			</geometry>
		</collision>
		<inertial>
			<mass value="2.2140298872108053"/>
			<inertia ixx="0.03" iyy="0.03" izz="0.03" ixy="0" ixz="0" iyz="0"/>
		</inertial>
	</link>
	<joint name="11_to_0" type="revolute">
		<parent link="0"/>
		<child link="11"/>
		<axis xyz="0 0 1"/>
		<limit effort="1" lower="0" upper="1" velocity="1"/>
		<origin rpy="5.076413026200689 2.729304377302126 0.7468481157876564" xyz="0.32240313226159123 0.5559093253829122 0.574642176438554"/>
	</joint>
	<joint name="22_to_11" type="fixed">
		<parent link="11"/>
		<child link="22"/>
		<axis xyz="0 0 1"/>
		<limit effort="1" lower="0" upper="1" velocity="1"/>
		<origin rpy="8.340417539526063 0.04277367990304956 2.353161705806918" xyz="0.38576345910918997 0.788060302792324 0.4082849509538302"/>
	</joint>
	<joint name="33_to_22" type="fixed">
		<parent link="22"/>
		<child link="33"/>
		<axis xyz="1 0 0"/>
		<limit effort="1" lower="0" upper="1" velocity="1"/>
		<origin rpy="8.626062360321292 4.066116495516653 0.17855683524773486" xyz="0.4019588800550753 0.05404209643720925 0.5053189571195247"/>
	</joint>
	<joint name="44_to_33" type="revolute">
		<parent link="33"/>
		<child link="44"/>
		<axis xyz="1 0 0"/>
		<limit effort="1" lower="0" upper="1" velocity="1"/>
		<origin rpy="9.21106065176765 1.7731205602841833 4.533725421018638" xyz="0.08074009831722107 0.05455108229915451 0.43227688328833513"/>
	</joint>
	<joint name="45_to_33" type="revolute">
		<parent link="33"/>
		<child link="45"/>
		<axis xyz="1 0 0"/>
		<limit effort="1" lower="0" upper="1" velocity="1"/>
		<origin rpy="13.816590977651474 1.7731205602841833 4.533725421018638" xyz="0.08074009831722107 0.05455108229915451 0.43227688328833513"/>
	</joint>
	<joint name="46_to_33" type="revolute">
		<parent link="33"/>
		<child link="46"/>
		<axis xyz="1 0 0"/>
		<limit effort="1" lower="0" upper="1" velocity="1"/>
		<origin rpy="18.4221213035353 1.7731205602841833 4.533725421018638" xyz="0.08074009831722107 0.05455108229915451 0.43227688328833513"/>
	</joint>
	<joint name="47_to_33" type="revolute">
		<parent link="33"/>
		<child link="47"/>
		<axis xyz="1 0 0"/>
		<limit effort="1" lower="0" upper="1" velocity="1"/>
		<origin rpy="23.027651629419125 1.7731205602841833 4.533725421018638" xyz="0.08074009831722107 0.05455108229915451 0.43227688328833513"/>
	</joint>
	<joint name="48_to_33" type="revolute">
		<parent link="33"/>
		<child link="48"/>
		<axis xyz="1 0 0"/>
		<limit effort="1" lower="0" upper="1" velocity="1"/>
		<origin rpy="27.63318195530295 1.7731205602841833 4.533725421018638" xyz="0.08074009831722107 0.05455108229915451 0.43227688328833513"/>
	</joint>
	<joint name="49_to_33" type="revolute">
		<parent link="33"/>
		<child link="49"/>
		<axis xyz="1 0 0"/>
		<limit effort="1" lower="0" upper="1" velocity="1"/>
		<origin rpy="32.23871228118677 1.7731205602841833 4.533725421018638" xyz="0.08074009831722107 0.05455108229915451 0.43227688328833513"/>
	</joint>
	<joint name="310_to_22" type="fixed">
		<parent link="22"/>
		<child link="310"/>
		<axis xyz="1 0 0"/>
		<limit effort="1" lower="0" upper="1" velocity="1"/>
		<origin rpy="12.939093540481938 4.066116495516653 0.17855683524773486" xyz="0.4019588800550753 0.05404209643720925 0.5053189571195247"/>
	</joint>
	<joint name="411_to_310" type="revolute">
		<parent link="310"/>
		<child link="411"/>
		<axis xyz="1 0 0"/>
		<limit effort="1" lower="0" upper="1" velocity="1"/>
		<origin rpy="9.21106065176765 1.7731205602841833 4.533725421018638" xyz="0.08074009831722107 0.05455108229915451 0.43227688328833513"/>
	</joint>
	<joint name="412_to_310" type="revolute">
		<parent link="310"/>
		<child link="412"/>
		<axis xyz="1 0 0"/>
		<limit effort="1" lower="0" upper="1" velocity="1"/>
		<origin rpy="13.816590977651474 1.7731205602841833 4.533725421018638" xyz="0.08074009831722107 0.05455108229915451 0.43227688328833513"/>
	</joint>
	<joint name="413_to_310" type="revolute">
		<parent link="310"/>
		<child link="413"/>
		<axis xyz="1 0 0"/>
		<limit effort="1" lower="0" upper="1" velocity="1"/>
		<origin rpy="18.4221213035353 1.7731205602841833 4.533725421018638" xyz="0.08074009831722107 0.05455108229915451 0.43227688328833513"/>
	</joint>
	<joint name="414_to_310" type="revolute">
		<parent link="310"/>
		<child link="414"/>
		<axis xyz="1 0 0"/>
		<limit effort="1" lower="0" upper="1" velocity="1"/>
		<origin rpy="23.027651629419125 1.7731205602841833 4.533725421018638" xyz="0.08074009831722107 0.05455108229915451 0.43227688328833513"/>
	</joint>
	<joint name="415_to_310" type="revolute">
		<parent link="310"/>
		<child link="415"/>
		<axis xyz="1 0 0"/>
		<limit effort="1" lower="0" upper="1" velocity="1"/>
		<origin rpy="27.63318195530295 1.7731205602841833 4.533725421018638" xyz="0.08074009831722107 0.05455108229915451 0.43227688328833513"/>
	</joint>
	<joint name="416_to_310" type="revolute">
		<parent link="310"/>
		<child link="416"/>
		<axis xyz="1 0 0"/>
		<limit effort="1" lower="0" upper="1" velocity="1"/>
		<origin rpy="32.23871228118677 1.7731205602841833 4.533725421018638" xyz="0.08074009831722107 0.05455108229915451 0.43227688328833513"/>
	</joint>
	<joint name="317_to_22" type="fixed">
		<parent link="22"/>
		<child link="317"/>
		<axis xyz="1 0 0"/>
		<limit effort="1" lower="0" upper="1" velocity="1"/>
		<origin rpy="17.252124720642584 4.066116495516653 0.17855683524773486" xyz="0.4019588800550753 0.05404209643720925 0.5053189571195247"/>
	</joint>
	<joint name="418_to_317" type="revolute">
		<parent link="317"/>
		<child link="418"/>
		<axis xyz="1 0 0"/>
		<limit effort="1" lower="0" upper="1" velocity="1"/>
		<origin rpy="9.21106065176765 1.7731205602841833 4.533725421018638" xyz="0.08074009831722107 0.05455108229915451 0.43227688328833513"/>
	</joint>
	<joint name="419_to_317" type="revolute">
		<parent link="317"/>
		<child link="419"/>
		<axis xyz="1 0 0"/>
		<limit effort="1" lower="0" upper="1" velocity="1"/>
		<origin rpy="13.816590977651474 1.7731205602841833 4.533725421018638" xyz="0.08074009831722107 0.05455108229915451 0.43227688328833513"/>
	</joint>
	<joint name="420_to_317" type="revolute">
		<parent link="317"/>
		<child link="420"/>
		<axis xyz="1 0 0"/>
		<limit effort="1" lower="0" upper="1" velocity="1"/>
		<origin rpy="18.4221213035353 1.7731205602841833 4.533725421018638" xyz="0.08074009831722107 0.05455108229915451 0.43227688328833513"/>
	</joint>
	<joint name="421_to_317" type="revolute">
		<parent link="317"/>
		<child link="421"/>
		<axis xyz="1 0 0"/>
		<limit effort="1" lower="0" upper="1" velocity="1"/>
		<origin rpy="23.027651629419125 1.7731205602841833 4.533725421018638" xyz="0.08074009831722107 0.05455108229915451 0.43227688328833513"/>
	</joint>
	<joint name="422_to_317" type="revolute">
		<parent link="317"/>
		<child link="422"/>
		<axis xyz="1 0 0"/>
		<limit effort="1" lower="0" upper="1" velocity="1"/>
		<origin rpy="27.63318195530295 1.7731205602841833 4.533725421018638" xyz="0.08074009831722107 0.05455108229915451 0.43227688328833513"/>
	</joint>
	<joint name="423_to_317" type="revolute">
		<parent link="317"/>
		<child link="423"/>
		<axis xyz="1 0 0"/>
		<limit effort="1" lower="0" upper="1" velocity="1"/>
		<origin rpy="32.23871228118677 1.7731205602841833 4.533725421018638" xyz="0.08074009831722107 0.05455108229915451 0.43227688328833513"/>
	</joint>
	<joint name="224_to_11" type="fixed">
		<parent link="11"/>
		<child link="224"/>
		<axis xyz="0 0 1"/>
		<limit effort="1" lower="0" upper="1" velocity="1"/>
		<origin rpy="12.510626309289094 0.04277367990304956 2.353161705806918" xyz="0.38576345910918997 0.788060302792324 0.4082849509538302"/>
	</joint>
	<joint name="325_to_224" type="fixed">
		<parent link="224"/>
		<child link="325"/>
		<axis xyz="1 0 0"/>
		<limit effort="1" lower="0" upper="1" velocity="1"/>
		<origin rpy="8.626062360321292 4.066116495516653 0.17855683524773486" xyz="0.4019588800550753 0.05404209643720925 0.5053189571195247"/>
	</joint>
	<joint name="426_to_325" type="revolute">
		<parent link="325"/>
		<child link="426"/>
		<axis xyz="1 0 0"/>
		<limit effort="1" lower="0" upper="1" velocity="1"/>
		<origin rpy="9.21106065176765 1.7731205602841833 4.533725421018638" xyz="0.08074009831722107 0.05455108229915451 0.43227688328833513"/>
	</joint>
	<joint name="427_to_325" type="revolute">
		<parent link="325"/>
		<child link="427"/>
		<axis xyz="1 0 0"/>
		<limit effort="1" lower="0" upper="1" velocity="1"/>
		<origin rpy="13.816590977651474 1.7731205602841833 4.533725421018638" xyz="0.08074009831722107 0.05455108229915451 0.43227688328833513"/>
	</joint>
	<joint name="428_to_325" type="revolute">
		<parent link="325"/>
		<child link="428"/>
		<axis xyz="1 0 0"/>
		<limit effort="1" lower="0" upper="1" velocity="1"/>
		<origin rpy="18.4221213035353 1.7731205602841833 4.533725421018638" xyz="0.08074009831722107 0.05455108229915451 0.43227688328833513"/>
	</joint>
	<joint name="429_to_325" type="revolute">
		<parent link="325"/>
		<child link="429"/>
		<axis xyz="1 0 0"/>
		<limit effort="1" lower="0" upper="1" velocity="1"/>
		<origin rpy="23.027651629419125 1.7731205602841833 4.533725421018638" xyz="0.08074009831722107 0.05455108229915451 0.43227688328833513"/>
	</joint>
	<joint name="430_to_325" type="revolute">
		<parent link="325"/>
		<child link="430"/>
		<axis xyz="1 0 0"/>
		<limit effort="1" lower="0" upper="1" velocity="1"/>
		<origin rpy="27.63318195530295 1.7731205602841833 4.533725421018638" xyz="0.08074009831722107 0.05455108229915451 0.43227688328833513"/>
	</joint>
	<joint name="431_to_325" type="revolute">
		<parent link="325"/>
		<child link="431"/>
		<axis xyz="1 0 0"/>
		<limit effort="1" lower="0" upper="1" velocity="1"/>
		<origin rpy="32.23871228118677 1.7731205602841833 4.533725421018638" xyz="0.08074009831722107 0.05455108229915451 0.43227688328833513"/>
	</joint>
	<joint name="332_to_224" type="fixed">
		<parent link="224"/>
		<child link="332"/>
		<axis xyz="1 0 0"/>
		<limit effort="1" lower="0" upper="1" velocity="1"/>
		<origin rpy="12.939093540481938 4.066116495516653 0.17855683524773486" xyz="0.4019588800550753 0.05404209643720925 0.5053189571195247"/>
	</joint>
	<joint name="433_to_332" type="revolute">
		<parent link="332"/>
		<child link="433"/>
		<axis xyz="1 0 0"/>
		<limit effort="1" lower="0" upper="1" velocity="1"/>
		<origin rpy="9.21106065176765 1.7731205602841833 4.533725421018638" xyz="0.08074009831722107 0.05455108229915451 0.43227688328833513"/>
	</joint>
	<joint name="434_to_332" type="revolute">
		<parent link="332"/>
		<child link="434"/>
		<axis xyz="1 0 0"/>
		<limit effort="1" lower="0" upper="1" velocity="1"/>
		<origin rpy="13.816590977651474 1.7731205602841833 4.533725421018638" xyz="0.08074009831722107 0.05455108229915451 0.43227688328833513"/>
	</joint>
	<joint name="435_to_332" type="revolute">
		<parent link="332"/>
		<child link="435"/>
		<axis xyz="1 0 0"/>
		<limit effort="1" lower="0" upper="1" velocity="1"/>
		<origin rpy="18.4221213035353 1.7731205602841833 4.533725421018638" xyz="0.08074009831722107 0.05455108229915451 0.43227688328833513"/>
	</joint>
	<joint name="436_to_332" type="revolute">
		<parent link="332"/>
		<child link="436"/>
		<axis xyz="1 0 0"/>
		<limit effort="1" lower="0" upper="1" velocity="1"/>
		<origin rpy="23.027651629419125 1.7731205602841833 4.533725421018638" xyz="0.08074009831722107 0.05455108229915451 0.43227688328833513"/>
	</joint>
	<joint name="437_to_332" type="revolute">
		<parent link="332"/>
		<child link="437"/>
		<axis xyz="1 0 0"/>
		<limit effort="1" lower="0" upper="1" velocity="1"/>
		<origin rpy="27.63318195530295 1.7731205602841833 4.533725421018638" xyz="0.08074009831722107 0.05455108229915451 0.43227688328833513"/>
	</joint>
	<joint name="438_to_332" type="revolute">
		<parent link="332"/>
		<child link="438"/>
		<axis xyz="1 0 0"/>
		<limit effort="1" lower="0" upper="1" velocity="1"/>
		<origin rpy="32.23871228118677 1.7731205602841833 4.533725421018638" xyz="0.08074009831722107 0.05455108229915451 0.43227688328833513"/>
	</joint>
	<joint name="339_to_224" type="fixed">
		<parent link="224"/>
		<child link="339"/>
		<axis xyz="1 0 0"/>
		<limit effort="1" lower="0" upper="1" velocity="1"/>
		<origin rpy="17.252124720642584 4.066116495516653 0.17855683524773486" xyz="0.4019588800550753 0.05404209643720925 0.5053189571195247"/>
	</joint>
	<joint name="440_to_339" type="revolute">
		<parent link="339"/>
		<child link="440"/>
		<axis xyz="1 0 0"/>
		<limit effort="1" lower="0" upper="1" velocity="1"/>
		<origin rpy="9.21106065176765 1.7731205602841833 4.533725421018638" xyz="0.08074009831722107 0.05455108229915451 0.43227688328833513"/>
	</joint>
	<joint name="441_to_339" type="revolute">
		<parent link="339"/>
		<child link="441"/>
		<axis xyz="1 0 0"/>
		<limit effort="1" lower="0" upper="1" velocity="1"/>
		<origin rpy="13.816590977651474 1.7731205602841833 4.533725421018638" xyz="0.08074009831722107 0.05455108229915451 0.43227688328833513"/>
	</joint>
	<joint name="442_to_339" type="revolute">
		<parent link="339"/>
		<child link="442"/>
		<axis xyz="1 0 0"/>
		<limit effort="1" lower="0" upper="1" velocity="1"/>
		<origin rpy="18.4221213035353 1.7731205602841833 4.533725421018638" xyz="0.08074009831722107 0.05455108229915451 0.43227688328833513"/>
	</joint>
	<joint name="443_to_339" type="revolute">
		<parent link="339"/>
		<child link="443"/>
		<axis xyz="1 0 0"/>
		<limit effort="1" lower="0" upper="1" velocity="1"/>
		<origin rpy="23.027651629419125 1.7731205602841833 4.533725421018638" xyz="0.08074009831722107 0.05455108229915451 0.43227688328833513"/>
	</joint>
	<joint name="444_to_339" type="revolute">
		<parent link="339"/>
		<child link="444"/>
		<axis xyz="1 0 0"/>
		<limit effort="1" lower="0" upper="1" velocity="1"/>
		<origin rpy="27.63318195530295 1.7731205602841833 4.533725421018638" xyz="0.08074009831722107 0.05455108229915451 0.43227688328833513"/>
	</joint>
	<joint name="445_to_339" type="revolute">
		<parent link="339"/>
		<child link="445"/>
		<axis xyz="1 0 0"/>
		<limit effort="1" lower="0" upper="1" velocity="1"/>
		<origin rpy="32.23871228118677 1.7731205602841833 4.533725421018638" xyz="0.08074009831722107 0.05455108229915451 0.43227688328833513"/>
	</joint>
</robot>
